Workbook
Name _Toc302395871: 'Sprint Backlog'!$A$4
Name _Toc302395872: 'Sprint Backlog'!#REF!
Name _Toc302395873: 'Sprint Backlog'!#REF!
Name _Toc302395874: 'Sprint Backlog'!#REF!
Name theyear: #REF!

Sheet Revision History
A1: Sprint Plan
A3: Revision History
A5: Version No | B5: Date | C5: Reason For Changes | D5: Author | E5: Reviewer | F5: Approver
A6: 0.01 | B6: 45548 | C6: Draft | D6: Saravana kumar M
A7: 0.02 | B7: 45551 | C7: Reviewed | D7: Saravana kumar M | E7: Sankar Ganesh
A8: 1 | B8: 45551 | C8: Baselined | D8: Saravana kumar M | E8: Sankar Ganesh | F8: Sankar Ganesh
G38: Sheet 17 of 17

Sheet Sprint Backlog
L2: Sprint Backlog
A4: Project Name/ID | B4: NOVPHILSCR | C4: Scrum Team ID | D4: NOVPHILSCR | E4: Product Owner | F4: NIJANTHAN PL | G4: Sprint Goal
A5: Project Manager | B5: SANKAR GANESH | C5: Sprint No | D5: 36 | E5: Scrum Master | F5: SARAVANA KUMAR M | G5: Need to complete all the taken user stories and deployed in live on time.
A7: S.No | B7: User Story ID | C7: Priority | D7: Size Estimation for User Story (Storypoints) | E7: Dependencies | F7: Definition of Done (DoD) | G7: Tasks | H7: Resource Name | I7: Planned Effort (in Hrs) | J7: Actual Effort (in Hrs) Day 1 | K7: Actual Effort (in Hrs) Day 2 | L7: Actual Effort (in Hrs) Day 3 | M7: Actual Effort (in Hrs) Day 4 | N7: Actual Effort (in Hrs) Day 5 | O7: Actual Effort (in Hrs) Day 6 | P7: Actual Effort (in Hrs) Day 7 | Q7: Actual Effort (in Hrs) Day 8 | R7: Actual Effort (in Hrs) Day 9 | S7: Actual Effort (in Hrs) Day 10
A8: 1 | B8: NOVPHILSCR-1994 | C8: High | D8: 8 | G8: Design | H8: MUTHURAJA | I8: 8 | J8: 7 | K8: 1
G9: Design Review | H9: DHANALAKSHMI | I9: 2
G10: Coding | H10: MUTHURAJA | I10: 12 | K10: 7 | L10: 5
G11: Code Review | H11: DHANALAKSHMI | I11: 1
G12: Unit Test Preparation | H12: MUTHURAJA | I12: 5 | L12: 2.5 | M12: 2.5
G13: Unit Test Review | H13: DHANALAKSHMI | I13: 1
G14: Unit Testing | H14: MUTHURAJA | I14: 5 | M14: 5
G15: Test Case & Scenario Preparation | H15: ANURAG KUMAR | I15: 6 | N15: 6
G16: Test Case Review | H16: DHANALAKSHMI | I16: 3
G17: Test Execution | H17: ANURAG KUMAR | I17: 8 | R17: 4 | S17: 3
A18: 2 | B18: NOVPHILSCR-2027 | C18: High | D18: 8 | G18: Design | H18: VENKATALAKSHMI | I18: 8 | J18: 3 | K18: 3 | L18: 2
G19: Design Review | H19: DHANALAKSHMI | I19: 2
G20: Coding | H20: VENKATALAKSHMI | I20: 12 | J20: 4.5 | K20: 4.5 | L20: 3
G21: Code Review | H21: DHANALAKSHMI | I21: 1
G22: Unit Test Preparation | H22: VENKATALAKSHMI | I22: 5 | L22: 2.5 | P22: 2.5
G23: Unit Test Review | H23: DHANALAKSHMI | I23: 1
G24: Unit Testing | H24: VENKATALAKSHMI | I24: 5 | M24: 2.5 | N24: 2.5
G25: Test Case & Scenario Preparation | H25: VINOTHINI | I25: 6
G26: Test Case Review | H26: DHANALAKSHMI | I26: 3
G27: Test Execution | H27: VINOTHINI | I27: 7
A28: 3 | B28: NOVPHILSCR-2104 | C28: High | D28: 8 | G28: Design | H28: NAGE GOWDA | I28: 8 | J28: 3 | K28: 3 | L28: 2
G29: Design Review | H29: DHANALAKSHMI | I29: 1
G30: Coding | H30: NAGE GOWDA | I30: 12 | J30: 4 | K30: 4 | L30: 4
G31: Code Review | H31: DHANALAKSHMI | I31: 1
G32: Unit Test Preparation | H32: NAGE GOWDA | I32: 5 | O32: 5
G33: Unit Test Review | H33: DHANALAKSHMI | I33: 1
G34: Unit Testing | H34: NAGE GOWDA | I34: 5 | P34: 5
G35: Test Case & Scenario Preparation | H35: RAVI RAJ | I35: 8 | J35: 3 | K35: 2.5 | L35: 2.5
G36: Test Case Review | H36: DHANALAKSHMI | I36: 2
G37: Test Execution | H37: RAVI RAJ | I37: 8 | P37: 3.5 | Q37: 4.5
A38: 4 | B38: NOVPHILSCR-2005 | C38: Medium | D38: 5 | G38: Design | H38: MUTHURAJA | I38: 8 | N38: 8
G39: Design Review | H39: DHANALAKSHMI | I39: 1
G40: Coding | H40: MUTHURAJA | I40: 8 | O40: 8
G41: Code Review | H41: DHANALAKSHMI | I41: 1
G42: Unit Test Preparation | H42: MUTHURAJA | I42: 3 | P42: 3
G43: Unit Test Review | H43: DHANALAKSHMI | I43: 1
...

Sheet Sprint Capacity Plan
A1: Sprint Capacity Plan
A5: Sprint Duration (In Days) | B5: 10 | C5: Start Date | D5: 45551 | E5: End Date | F5: 45565 | G5: Sprint Review & Retro Date | H5: 45565
A6: Capacity (in Hours)
A7: Resource Name | B7: Planned Leave (in Hours) | C7: Per Day (in Hours) | D7: Sprint (Per Resource in Hours) | E7: Available capacity(in Hrs) | F7: Task Planned (in Hrs) | G7: Available (in Hrs) | H7: Load %
A8: MUTHURAJA | C8: 8 | D8: =C8*B5 -> 80 | E8: 80 | F8: 74 | G8: =E8-F8 -> 6 | H8: =(F8/E8)*100 -> 92.5
A9: NAGE GOWDA | C9: 8 | D9: =C9*B5 -> 80 | E9: 80 | F9: 30 | G9: =E9-F9 -> 50 | H9: =(F9/E9)*100 -> 37.5
A10: VENKATALAKSHMI | C10: 8 | D10: 80 | E10: 80 | F10: 60 | G10: =E10-F10 -> 20 | H10: =(F10/E10)*100 -> 75
A11: VINOTHINI | C11: 4 | D11: 40 | E11: 40 | F11: 40 | G11: =E11-F11 -> 0 | H11: =(F11/E11)*100 -> 100
A12: ANURAG KUMAR | C12: 4 | D12: 40 | E12: 40 | F12: 32 | G12: =E12-F12 -> 8 | H12: =(F12/E12)*100 -> 80
A13: DHANALAKSHMI | B13: 8 | C13: 4 | D13: =C13*B5 -> 40 | E13: 32 | F13: 32 | G13: =E13-F13 -> 0 | H13: =(F13/E13)*100 -> 100
A14: RAVI RAJ | C14: 4 | D14: 40 | E14: 40 | F14: 16 | G14: =E14-F14 -> 24 | H14: =(F14/E14)*100 -> 40
D15: =SUM(D8:D14) -> 400 | E15: =SUM(E8:E14) -> 392 | F15: =SUM(F8:F14) -> 284 | G15: =E15-F15 -> 108 | H15: =AVERAGE(H8:H14) -> 75

Sheet Sprint Burndown chart
K2: Sprint Burndown chart
A4: Sprint BurnDown chart : Day Wise Data
C7: Sprint Burn down Data
C8: Day | D8: Total Planned Hours | E8: Capacity (in Hours) | F8: Actual Effort Burnt | G8: Actual Hours
C9: Day 0 | D9: ='Sprint Backlog'!I68 -> 282
C10: Day 1 | D10: =D9-E10 -> 242 | E10: 40 | F10: =D9-G10 -> 254 | G10: ='Sprint Backlog'!J68 -> 28
C11: Day 2 | D11: =D10-E11 -> 202 | E11: 40 | F11: =F10-G11 -> 212.5 | G11: ='Sprint Backlog'!K68 -> 41.5
C12: Day 3 | D12: =D11-E12 -> 162 | E12: 40 | F12: =F11-G12 -> 181.5 | G12: ='Sprint Backlog'!L68 -> 31
C13: Day 4 | D13: =D12-E13 -> 122 | E13: 40 | F13: =F12-G13 -> 162.5 | G13: ='Sprint Backlog'!M68 -> 19
C14: Day 5 | D14: =D13-E14 -> 82 | E14: 40 | F14: =F13-G14 -> 146 | G14: ='Sprint Backlog'!N68 -> 16.5
C15: Day 6 | D15: =D14-E15 -> 42 | E15: 40 | F15: =F14-G15 -> 123.5 | G15: ='Sprint Backlog'!O68 -> 22.5
C16: Day 7 | D16: =D15-E16 -> 2 | E16: 40 | F16: =F15-G16 -> 95.5 | G16: ='Sprint Backlog'!P68 -> 28
C17: Day 8 | D17: =D16-E17 -> -38 | E17: 40 | F17: =F16-G17 -> 76.5 | G17: ='Sprint Backlog'!Q68 -> 19
C18: Day 9 | D18: =D17-E18 -> -78 | E18: 40 | F18: =F17-G18 -> 53.5 | G18: ='Sprint Backlog'!R68 -> 23
C19: Day 10 | D19: =D18-E19 -> -118 | E19: 40 | F19: =F18-G19 -> 41.5 | G19: ='Sprint Backlog'!S68 -> 12
A30: Sprint BurnDown Chart
A32: It is metric that compares actual and expected progress and shows whether the team is ahead or behind the expectations. ( Provide inference based on the chart)
